<?xml version="1.0" encoding="utf-8"?>
<!-- This URDF was automatically created by SolidWorks to URDF Exporter! Originally created by Stephen Brawner (brawner@gmail.com) 
     Commit Version: 1.6.0-4-g7f85cfe  Build Version: 1.6.7995.38578
     For more information, please see http://wiki.ros.org/sw_urdf_exporter -->
<robot
  name="urdf_v5">
  <link
    name="base_link">
    <inertial>
      <origin
        xyz="0.00332576617239533 0.000338299096548381 0.016292511278978"
        rpy="0 0 0" />
      <mass
        value="1.76383778742641" />
      <inertia
        ixx="0.00482252709333626"
        ixy="4.979211345609E-06"
        ixz="4.30164694385565E-14"
        iyy="0.00236335725347059"
        iyz="-4.36088020352683E-14"
        izz="0.00668984934486886" />
    </inertial>
    <visual>
      <origin
        xyz="0 0 0"
        rpy="0 0 0" />
      <geometry>
        <mesh
          filename="package://urdf_v5/meshes/base_link.STL" />
      </geometry>
      <material
        name="">
        <color
          rgba="1 1 1 1" />
      </material>
    </visual>
    <collision>
      <origin
        xyz="0 0 0"
        rpy="0 0 0" />
      <geometry>
        <mesh
          filename="package://urdf_v5/meshes/base_link.STL" />
      </geometry>
    </collision>
  </link>
  <link
    name="w 0">
    <inertial>
      <origin
        xyz="-0.00777817459305208 0.00777817459305172 -6.48786580015326E-16"
        rpy="0 0 0" />
      <mass
        value="0.464547305686323" />
      <inertia
        ixx="0.00101544234181709"
        ixy="-0.000315253415321381"
        ixz="4.7686962313682E-21"
        iyy="0.00101544234181709"
        iyz="-8.95753885333674E-21"
        izz="0.00070018892649571" />
    </inertial>
    <visual>
      <origin
        xyz="0 0 0"
        rpy="0 0 0" />
      <geometry>
        <mesh
          filename="package://urdf_v5/meshes/w 0.STL" />
      </geometry>
      <material
        name="">
        <color
          rgba="0.792156862745098 0.819607843137255 0.933333333333333 1" />
      </material>
    </visual>
    <collision>
      <origin
        xyz="0 0 0"
        rpy="0 0 0" />
      <geometry>
        <mesh
          filename="package://urdf_v5/meshes/w 0.STL" />
      </geometry>
    </collision>
  </link>
  <joint
    name="wojoint"
    type="continuous">
    <origin
      xyz="0.172060894977629 -0.172060894977632 0.00364575766833166"
      rpy="0 0 0" />
    <parent
      link="base_link" />
    <child
      link="w 0" />
    <axis
      xyz="0.707106781186545 -0.70710678118655 0" />
  </joint>
  <link
    name="w 1">
    <inertial>
      <origin
        xyz="-0.00777817459305163 -0.00777817459305227 -6.6266436782314E-16"
        rpy="0 0 0" />
      <mass
        value="0.464547305686322" />
      <inertia
        ixx="0.00101544234181709"
        ixy="0.00031525341532138"
        ixz="3.26893506274833E-20"
        iyy="0.00101544234181709"
        iyz="2.59693353311023E-20"
        izz="0.000700188926495709" />
    </inertial>
    <visual>
      <origin
        xyz="0 0 0"
        rpy="0 0 0" />
      <geometry>
        <mesh
          filename="package://urdf_v5/meshes/w 1.STL" />
      </geometry>
      <material
        name="">
        <color
          rgba="0.792156862745098 0.819607843137255 0.933333333333333 1" />
      </material>
    </visual>
    <collision>
      <origin
        xyz="0 0 0"
        rpy="0 0 0" />
      <geometry>
        <mesh
          filename="package://urdf_v5/meshes/w 1.STL" />
      </geometry>
    </collision>
  </link>
  <joint
    name="w1joint"
    type="continuous">
    <origin
      xyz="0.172060894977632 0.172060894977629 0.00364575766833166"
      rpy="0 0 0" />
    <parent
      link="base_link" />
    <child
      link="w 1" />
    <axis
      xyz="0.707106781186547 0.707106781186548 0" />
  </joint>
  <link
    name="w 2">
    <inertial>
      <origin
        xyz="0.00777817459305252 -0.00777817459305177 -6.48786580015326E-16"
        rpy="0 0 0" />
      <mass
        value="0.464547305686322" />
      <inertia
        ixx="0.00101544234181709"
        ixy="-0.00031525341532138"
        ixz="-1.02835093752593E-20"
        iyy="0.00101544234181709"
        iyz="4.48331892003739E-22"
        izz="0.000700188926495709" />
    </inertial>
    <visual>
      <origin
        xyz="0 0 0"
        rpy="0 0 0" />
      <geometry>
        <mesh
          filename="package://urdf_v5/meshes/w 2.STL" />
      </geometry>
      <material
        name="">
        <color
          rgba="0.792156862745098 0.819607843137255 0.933333333333333 1" />
      </material>
    </visual>
    <collision>
      <origin
        xyz="0 0 0"
        rpy="0 0 0" />
      <geometry>
        <mesh
          filename="package://urdf_v5/meshes/w 2.STL" />
      </geometry>
    </collision>
  </link>
  <joint
    name="w2joint"
    type="continuous">
    <origin
      xyz="-0.17206089497763 0.172060894977632 0.00364575766833366"
      rpy="0 0 0" />
    <parent
      link="base_link" />
    <child
      link="w 2" />
    <axis
      xyz="-0.70710678118655 0.707106781186545 0" />
  </joint>
  <link
    name="w 3">
    <inertial>
      <origin
        xyz="0.00777817459305152 0.00777817459305251 -6.86950496486816E-16"
        rpy="0 0 0" />
      <mass
        value="0.464547305686322" />
      <inertia
        ixx="0.00101544234181709"
        ixy="0.000315253415321381"
        ixz="3.29168252959351E-20"
        iyy="0.0010154423418171"
        iyz="-3.14973833647942E-20"
        izz="0.000700188926495709" />
    </inertial>
    <visual>
      <origin
        xyz="0 0 0"
        rpy="0 0 0" />
      <geometry>
        <mesh
          filename="package://urdf_v5/meshes/w 3.STL" />
      </geometry>
      <material
        name="">
        <color
          rgba="0.792156862745098 0.819607843137255 0.933333333333333 1" />
      </material>
    </visual>
    <collision>
      <origin
        xyz="0 0 0"
        rpy="0 0 0" />
      <geometry>
        <mesh
          filename="package://urdf_v5/meshes/w 3.STL" />
      </geometry>
    </collision>
  </link>
  <joint
    name="w3joint"
    type="continuous">
    <origin
      xyz="-0.172060894977631 -0.17206089497763 0.00364575766833166"
      rpy="0 0 0" />
    <parent
      link="base_link" />
    <child
      link="w 3" />
    <axis
      xyz="-0.707106781186542 -0.707106781186553 0" />
  </joint>
  <link
    name="yaw">
    <inertial>
      <origin
        xyz="-0.000104829761399028 0.000589227103042572 0.140842550671345"
        rpy="0 0 0" />
      <mass
        value="0.883658426613258" />
      <inertia
        ixx="0.00213024726017061"
        ixy="5.73528912951601E-05"
        ixz="-2.42952454253992E-06"
        iyy="0.00206248069839823"
        iyz="-2.22795485506688E-05"
        izz="0.00270809171358489" />
    </inertial>
    <visual>
      <origin
        xyz="0 0 0"
        rpy="0 0 0" />
      <geometry>
        <mesh
          filename="package://urdf_v5/meshes/yaw.STL" />
      </geometry>
      <material
        name="">
        <color
          rgba="1 1 1 1" />
      </material>
    </visual>
    <collision>
      <origin
        xyz="0 0 0"
        rpy="0 0 0" />
      <geometry>
        <mesh
          filename="package://urdf_v5/meshes/yaw.STL" />
      </geometry>
    </collision>
  </link>
  <joint
    name="yawjoint"
    type="continuous">
    <origin
      xyz="0 0 0"
      rpy="0 0 0" />
    <parent
      link="base_link" />
    <child
      link="yaw" />
    <axis
      xyz="0 0 -1" />
  </joint>
  <link
    name="ph">
    <inertial>
      <origin
        xyz="-0.0096505322715873 0.00102702125391747 0.048172682863894"
        rpy="0 0 0" />
      <mass
        value="0.90065945763592" />
      <inertia
        ixx="0.00107450925105923"
        ixy="-3.76418436284026E-07"
        ixz="-0.000214486770726335"
        iyy="0.000927972485119108"
        iyz="-1.67879377110663E-07"
        izz="0.0015213979001916" />
    </inertial>
    <visual>
      <origin
        xyz="0 0 0"
        rpy="0 0 0" />
      <geometry>
        <mesh
          filename="package://urdf_v5/meshes/ph.STL" />
      </geometry>
      <material
        name="">
        <color
          rgba="1 1 1 1" />
      </material>
    </visual>
    <collision>
      <origin
        xyz="0 0 0"
        rpy="0 0 0" />
      <geometry>
        <mesh
          filename="package://urdf_v5/meshes/ph.STL" />
      </geometry>
    </collision>
  </link>
  <joint
    name="phjo"
    type="revolute">
    <origin
      xyz="0 0 0.291"
      rpy="0 0 0.11442" />
    <parent
      link="yaw" />
    <child
      link="ph" />
    <axis
      xyz="0 -1 0" />
    <limit
      lower="0"
      upper="0"
      effort="0"
      velocity="0" />
  </joint>
</robot>